Workbook
Name Slicer_Age_Group: #N/A
Name Slicer_credit_risk_label: #N/A
Name Slicer_employment_status: #N/A
Name Slicer_gender: #N/A

Sheet Raw_data
A1: customer_id | B1: age | C1: gender | D1: employment_status | E1: annual_income | F1: account_age_months | G1: avg_monthly_balance | H1: num_deposits_per_month | I1: avg_deposit_amount | J1: debit_card_usage_frequency | K1: debit_card_spending | L1: mobile_banking_logins | M1: online_transfer_frequency | N1: atm_withdrawal_frequency | O1: credit_score | P1: num_open_loans | Q1: total_outstanding_debt | R1: late_payment_count | S1: loan_default_history | T1: fraud_flag | U1: loan_application_amount | V1: credit_risk
A2: CUST_00000 | B2: 58 | C2: Male | D2: Unemployed | E2: 58137.751 | F2: 115 | G2: 524.67941 | H2: 1 | I2: 171.34237 | J2: 49 | K2: 768.87751 | L2: 9 | M2: 16 | N2: 1 | O2: 539 | P2: 5 | Q2: 14435.423 | R2: 2 | S2: 0 | T2: 0 | U2: 15510.577 | V2: 1
A3: CUST_00001 | B3: 48 | C3: Male | D3: Self-Employed | E3: 26174.923 | F3: 32 | G3: 2635.2034 | H3: 1 | I3: 985.60716 | J3: 1 | K3: 580.28779 | L3: 9 | M3: 1 | N3: 2 | O3: 494 | P3: 5 | Q3: 11263.099 | R3: 2 | S3: 0 | T3: 0 | U3: 14819.436 | V3: 1
A4: CUST_00002 | B4: 34 | C4: Other | D4: Unemployed | E4: 75566.837 | F4: 14 | G4: 2334.3411 | H4: 9 | I4: 994.31012 | J4: 42 | K4: 564.01351 | L4: 36 | M4: 5 | N4: 6 | O4: 437 | P4: 3 | Q4: 15017.144 | R4: 5 | S4: 0 | T4: 0 | U4: 10909.807 | V4: 1
A5: CUST_00003 | B5: 62 | C5: Male | D5: Self-Employed | E5: 35197.962 | F5: 179 | G5: 2425.3843 | H5: 10 | I5: 366.11535 | J5: 4 | K5: 838.4892 | L5: 31 | M5: 7 | N5: 7 | O5: 809 | P5: 1 | Q5: 12626.138 | R5: 2 | S5: 0 | T5: 0 | U5: 500 | V5: 0
A6: CUST_00004 | B6: 27 | C6: Female | D6: Self-Employed | E6: 12136.998 | F6: 225 | G6: 10 | H6: 8 | I6: 786.75226 | J6: 16 | K6: 462.49552 | L6: 35 | M6: 16 | N6: 3 | O6: 522 | P6: 1 | Q6: 13576.704 | R6: 4 | S6: 0 | T6: 0 | U6: 9514.5916 | V6: 1
A7: CUST_00005 | B7: 40 | C7: Male | D7: Employed | E7: 76906.812 | F7: 84 | G7: 1260.6545 | H7: 2 | I7: 227.11026 | J7: 36 | K7: 0 | L7: 63 | M7: 5 | N7: 7 | O7: 727 | P7: 4 | Q7: 1267.3283 | R7: 2 | S7: 0 | T7: 0 | U7: 5424.0245 | V7: 0
A8: CUST_00006 | B8: 58 | C8: Female | D8: Employed | E8: 14485.73 | F8: 48 | G8: 1437.594 | H8: 3 | I8: 20 | J8: 34 | K8: 633.58911 | L8: 14 | M8: 11 | N8: 0 | O8: 754 | P8: 1 | Q8: 13356.388 | R8: 2 | S8: 1 | T8: 0 | U8: 9004.5822 | V8: 1
A9: CUST_00007 | B9: 38 | C9: Female | D9: Employed | E9: 67355.218 | F9: 173 | G9: 1959.9972 | H9: 0 | I9: 426.24332 | J9: 7 | K9: 788.1865 | L9: 72 | M9: 15 | N9: 2 | O9: 307 | P9: 5 | Q9: 18254.854 | R9: 5 | S9: 0 | T9: 0 | U9: 12632.806 | V9: 1
A10: CUST_00008 | B10: 42 | C10: Female | D10: Employed | E10: 62980.151 | F10: 132 | G10: 2220.6996 | H10: 0 | I10: 584.18127 | J10: 42 | K10: 618.81375 | L10: 15 | M10: 5 | N10: 3 | O10: 515 | P10: 3 | Q10: 8376.6864 | R10: 7 | S10: 0 | T10: 0 | U10: 9538.7568 | V10: 1
A11: CUST_00009 | B11: 30 | C11: Female | D11: Self-Employed | E11: 55751.974 | F11: 99 | G11: 2527.7005 | H11: 3 | I11: 1025.4897 | J11: 2 | K11: 180.2633 | L11: 45 | M11: 1 | N11: 4 | O11: 583 | P11: 1 | Q11: 17976.627 | R11: 6 | S11: 0 | T11: 0 | U11: 2896.6703 | V11: 1
A12: CUST_00010 | B12: 30 | C12: Female | D12: Unemployed | E12: 40590.051 | F12: 205 | G12: 10 | H12: 1 | I12: 823.59283 | J12: 2 | K12: 339.64213 | L12: 43 | M12: 2 | N12: 8 | O12: 792 | P12: 3 | Q12: 9880.3197 | R12: 7 | S12: 0 | T12: 0 | U12: 1746.5996 | V12: 1
A13: CUST_00011 | B13: 43 | C13: Male | D13: Employed | E13: 59050.351 | F13: 228 | G13: 858.95961 | H13: 7 | I13: 832.74091 | J13: 0 | K13: 465.153 | L13: 75 | M13: 8 | N13: 1 | O13: 738 | P13: 4 | Q13: 8443.4583 | R13: 4 | S13: 0 | T13: 0 | U13: 4463.367 | V13: 1
... A5001: CUST_04999 | B5001: 42 | C5001: Other | D5001: Self-Employed | E5001: 68278.151 | F5001: 136 | G5001: 1095.1232 | H5001: 7 | I5001: 1335.5331 | J5001: 11 | K5001: 569.36978 | L5001: 2 | M5001: 16 | N5001: 6 | O5001: 431 | P5001: 4 | Q5001: 17730.576 | R5001: 3 | S5001: 0 | T5001: 0 | U5001: 16552.935 | V5001: 1

Sheet Data_Cleaning
A1: Bank Credit Risk Analytics
A2: Data Cleaning Report
A5: Dataset Information
A7: Metric | B7: Value
A8: Total Records | B8: =ROWS(Bank_data[]) -> 5000
A9: Total Columns | B9: =COLUMNS(Bank_data[]) -> 22
A10: Dataset Name | B10: Credit Risk Dataset
A11: Data Source | B11: Kaggle
A12: Date Imported | B12: =TODAY() -> 46220
A15: Missing Value Analysis
A17: Column Name | B17: Missing Values | C17: Missing % | D17: Status
A18: customer_id | B18: =COUNTBLANK(Bank_data[customer_id]) -> 0 | C18: =B18/ROWS(Bank_data[]) -> 0 | D18: =IF(B18=0,"Pass","Needs Review") -> Pass
A19: age | B19: =COUNTBLANK(Bank_data[age]) -> 0 | C19: =B19/ROWS(Bank_data[]) -> 0 | D19: =IF(B19=0,"Pass","Needs Review") -> Pass
A20: gender | B20: =COUNTBLANK(Bank_data[gender]) -> 0 | C20: =B20/ROWS(Bank_data[]) -> 0 | D20: =IF(B20=0,"Pass","Needs Review") -> Pass
A21: employment_status | B21: =COUNTBLANK(Bank_data[employment_status]) -> 0 | C21: =B21/ROWS(Bank_data[]) -> 0 | D21: =IF(B21=0,"Pass","Needs Review") -> Pass
A22: annual_income | B22: =COUNTBLANK(Bank_data[annual_income]) -> 0 | C22: =B22/ROWS(Bank_data[]) -> 0 | D22: =IF(B22=0,"Pass","Needs Review") -> Pass
A23: credit_score | B23: =COUNTBLANK(Bank_data[gender]) -> 0 | C23: =B23/ROWS(Bank_data[]) -> 0 | D23: =IF(B23=0,"Pass","Needs Review") -> Pass
A24: total_outstanding_debt | B24: =COUNTBLANK(Bank_data[total_outstanding_debt]) -> 0 | C24: =B24/ROWS(Bank_data[]) -> 0 | D24: =IF(B24=0,"Pass","Needs Review") -> Pass
A25: loan_application_amount | B25: =COUNTBLANK(Bank_data[gender]) -> 0 | C25: =B25/ROWS(Bank_data[]) -> 0 | D25: =IF(B25=0,"Pass","Needs Review") -> Pass
A26: loan_default_history | B26: =COUNTBLANK(Bank_data[loan_default_history]) -> 0 | C26: =B26/ROWS(Bank_data[]) -> 0 | D26: =IF(B26=0,"Pass","Needs Review") -> Pass
A27: fraud_flag | B27: =COUNTBLANK(Bank_data[fraud_flag]) -> 0 | C27: =B27/ROWS(Bank_data[]) -> 0 | D27: =IF(B27=0,"Pass","Needs Review") -> Pass
A30: Duplicate Analysis
A32: Metric | B32: Method | C32: Result | D32: Status
A33: Duplicate Customer IDs | B33: Excel Remove Duplicates | C33: 0 | D33: Pass
A34: Duplicate Rows | B34: Data → Remove Duplicates | C34: No duplicate values found | D34: Pass
A35: Action Taken | B35: Manual Verification | C35: No records removed | D35: Completed
A40: Analyst Observation
A41: A duplicate analysis was performed using Excel's Remove Duplicates tool across all columns. No duplicate values were found, confirming that each customer record is unique. As a result, no records were removed, and the dataset maintains a high level of data integrity for further analysis.
A45: Validation Checks
A46: Validation Rule | B46: Formula | C46: Result | D46: Status
A48: Age less than 18 | B48: =COUNTIF(Bank_data[age],"<18") -> 0 | C48: =COUNTIF(Raw_data!B2:B5001,"<18") -> 0 | D48: =IF(C48=0,"Pass","Review") -> Pass
A49: Age greater than 100 | B49: =COUNTIF(Bank_data[age],">100") -> 0 | C49: =COUNTIF(Raw_data!B2:B5001,">100") -> 0 | D49: =IF(C49=0,"Pass","Review") -> Pass
A50: Negative Annual Income | B50: =COUNTIF(Bank_data[annual_income],"<0") -> 0 | C50: =COUNTIF(Raw_data!E2:E5001,"<0") -> 0 | D50: =IF(C50=0,"Pass","Review") -> Pass
A51: Negative Outstanding Debt | B51: =COUNTIF(Bank_data[total_outstanding_debt],"<0") -> 0 | C51: =COUNTIF(Raw_data!Q2:Q5001,"<0") -> 0 | D51: =IF(C51=0,"Pass","Review") -> Pass
A52: Credit Score below 300 | B52: =COUNTIF(Bank_data[credit_score],"<300") -> 0 | C52: =COUNTIF(Raw_data!O2:O5001,"<300") -> 0 | D52: =IF(C52=0,"Pass","Review") -> Pass
A53: Credit Score above 850 | B53: =COUNTIF(Bank_data[credit_score],">900") -> 0 | C53: =COUNTIF(Bank_data[credit_score],">900") -> 0 | D53: =IF(C53=0,"Pass","Review") -> Pass
A54: Negative Loan Amount | B54: =COUNTIF(Bank_data[loan_application_amount],"<0") -> 0 | C54: =COUNTIF(Raw_data!U2:U5001,"<0") -> 0 | D54: =IF(C54=0,"Pass","Review") -> Pass
A58: Overall Data Quality Score
A60: Metric | B60: Value
A61: Total Validation Checks | B61: 7
...

Sheet Feature Engineering
A1: Bank Credit Risk Analytics – Feature Engineering
A3: Purpose
A4: This worksheet creates new business features from the raw customer data to support risk analysis, customer segmentation, and dashboard reporting.
A6: customer_id | B6: age | C6: gender | D6: employment_status | E6: annual_income | F6: account_age_months | G6: avg_monthly_balance | H6: num_deposits_per_month | I6: avg_deposit_amount | J6: debit_card_usage_frequency | K6: debit_card_spending | L6: mobile_banking_logins | M6: online_transfer_frequency | N6: atm_withdrawal_frequency | O6: credit_score | P6: num_open_loans | Q6: total_outstanding_debt | R6: late_payment_count | S6: loan_default_history | T6: fraud_flag | U6: loan_application_amount | V6: credit_risk | W6: credit_risk_label | X6: Age_Group | Y6: Income_Band | Z6: Credit_Score_Band | AA6: Debt_to_Income_Ratio | AB6: Balance_Category | AC6: Digital_Engagement | AD6: High_Value_Customer
A7: CUST_00000 | B7: 58 | C7: Male | D7: Unemployed | E7: 58137.751 | F7: 115 | G7: 524.67941 | H7: 1 | I7: 171.34237 | J7: 49 | K7: 768.87751 | L7: 9 | M7: 16 | N7: 1 | O7: 539 | P7: 5 | Q7: 14435.423 | R7: 2 | S7: 0 | T7: 0 | U7: 15510.577 | V7: 1 | W7: =IF(Bank_data3[[#This Row],[credit_risk]]=1,"High Risk","Low Risk") -> High Risk | X7: =_xlfn.IFS(B7<25,"18-24",B7<35,"25-34",B7<45,"35-44",B7<55,"45-54",TRUE(),"55+") -> 55+ | Y7: =_xlfn.IFS(E7<50000,"Low Income",E7<100000,"Middle Income",TRUE(),"High Income") -> Middle Income | Z7: =_xlfn.IFS(O7<580,"Poor",O7<670,"Fair",O7<740,"Good",O7<800,"Very Good",TRUE(),"Excellent") -> Poor | AA7: =IF(E7=0,0,Q7/E7) -> 0.2482969 | AB7: =_xlfn.IFS(G7<1000,"Low",G7<5000,"Medium",TRUE(),"High") -> Low | AC7: =_xlfn.IFS(L7<10,"Low",L7<30,"Medium",TRUE(),"High") -> Low | AD7: =IF(AND(E7>=100000,O7>=750),"Yes","No") -> No
A8: CUST_00001 | B8: 48 | C8: Male | D8: Self-Employed | E8: 26174.923 | F8: 32 | G8: 2635.2034 | H8: 1 | I8: 985.60716 | J8: 1 | K8: 580.28779 | L8: 9 | M8: 1 | N8: 2 | O8: 494 | P8: 5 | Q8: 11263.099 | R8: 2 | S8: 0 | T8: 0 | U8: 14819.436 | V8: 1 | W8: =IF(Bank_data3[[#This Row],[credit_risk]]=1,"High Risk","Low Risk") -> High Risk | X8: =_xlfn.IFS(B8<25,"18-24",B8<35,"25-34",B8<45,"35-44",B8<55,"45-54",TRUE(),"55+") -> 45-54 | Y8: =_xlfn.IFS(E8<50000,"Low Income",E8<100000,"Middle Income",TRUE(),"High Income") -> Low Income | Z8: =_xlfn.IFS(O8<580,"Poor",O8<670,"Fair",O8<740,"Good",O8<800,"Very Good",TRUE(),"Excellent") -> Poor | AA8: =IF(E8=0,0,Q8/E8) -> 0.43030115 | AB8: =_xlfn.IFS(G8<1000,"Low",G8<5000,"Medium",TRUE(),"High") -> Medium | AC8: =_xlfn.IFS(L8<10,"Low",L8<30,"Medium",TRUE(),"High") -> Low | AD8: =IF(AND(E8>=100000,O8>=750),"Yes","No") -> No
A9: CUST_00002 | B9: 34 | C9: Other | D9: Unemployed | E9: 75566.837 | F9: 14 | G9: 2334.3411 | H9: 9 | I9: 994.31012 | J9: 42 | K9: 564.01351 | L9: 36 | M9: 5 | N9: 6 | O9: 437 | P9: 3 | Q9: 15017.144 | R9: 5 | S9: 0 | T9: 0 | U9: 10909.807 | V9: 1 | W9: =IF(Bank_data3[[#This Row],[credit_risk]]=1,"High Risk","Low Risk") -> High Risk | X9: =_xlfn.IFS(B9<25,"18-24",B9<35,"25-34",B9<45,"35-44",B9<55,"45-54",TRUE(),"55+") -> 25-34 | Y9: =_xlfn.IFS(E9<50000,"Low Income",E9<100000,"Middle Income",TRUE(),"High Income") -> Middle Income | Z9: =_xlfn.IFS(O9<580,"Poor",O9<670,"Fair",O9<740,"Good",O9<800,"Very Good",TRUE(),"Excellent") -> Poor | AA9: =IF(E9=0,0,Q9/E9) -> 0.19872665 | AB9: =_xlfn.IFS(G9<1000,"Low",G9<5000,"Medium",TRUE(),"High") -> Medium | AC9: =_xlfn.IFS(L9<10,"Low",L9<30,"Medium",TRUE(),"High") -> High | AD9: =IF(AND(E9>=100000,O9>=750),"Yes","No") -> No
A10: CUST_00003 | B10: 62 | C10: Male | D10: Self-Employed | E10: 35197.962 | F10: 179 | G10: 2425.3843 | H10: 10 | I10: 366.11535 | J10: 4 | K10: 838.4892 | L10: 31 | M10: 7 | N10: 7 | O10: 809 | P10: 1 | Q10: 12626.138 | R10: 2 | S10: 0 | T10: 0 | U10: 500 | V10: 0 | W10: =IF(Bank_data3[[#This Row],[credit_risk]]=1,"High Risk","Low Risk") -> Low Risk | X10: =_xlfn.IFS(B10<25,"18-24",B10<35,"25-34",B10<45,"35-44",B10<55,"45-54",TRUE(),"55+") -> 55+ | Y10: =_xlfn.IFS(E10<50000,"Low Income",E10<100000,"Middle Income",TRUE(),"High Income") -> Low Income | Z10: =_xlfn.IFS(O10<580,"Poor",O10<670,"Fair",O10<740,"Good",O10<800,"Very Good",TRUE(),"Excellent") -> Excellent | AA10: =IF(E10=0,0,Q10/E10) -> 0.35871789 | AB10: =_xlfn.IFS(G10<1000,"Low",G10<5000,"Medium",TRUE(),"High") -> Medium | AC10: =_xlfn.IFS(L10<10,"Low",L10<30,"Medium",TRUE(),"High") -> High | AD10: =IF(AND(E10>=100000,O10>=750),"Yes","No") -> No
A11: CUST_00004 | B11: 27 | C11: Female | D11: Self-Employed | E11: 12136.998 | F11: 225 | G11: 10 | H11: 8 | I11: 786.75226 | J11: 16 | K11: 462.49552 | L11: 35 | M11: 16 | N11: 3 | O11: 522 | P11: 1 | Q11: 13576.704 | R11: 4 | S11: 0 | T11: 0 | U11: 9514.5916 | V11: 1 | W11: =IF(Bank_data3[[#This Row],[credit_risk]]=1,"High Risk","Low Risk") -> High Risk | X11: =_xlfn.IFS(B11<25,"18-24",B11<35,"25-34",B11<45,"35-44",B11<55,"45-54",TRUE(),"55+") -> 25-34 | Y11: =_xlfn.IFS(E11<50000,"Low Income",E11<100000,"Middle Income",TRUE(),"High Income") -> Low Income | Z11: =_xlfn.IFS(O11<580,"Poor",O11<670,"Fair",O11<740,"Good",O11<800,"Very Good",TRUE(),"Excellent") -> Poor | AA11: =IF(E11=0,0,Q11/E11) -> 1.1186213 | AB11: =_xlfn.IFS(G11<1000,"Low",G11<5000,"Medium",TRUE(),"High") -> Low | AC11: =_xlfn.IFS(L11<10,"Low",L11<30,"Medium",TRUE(),"High") -> High | AD11: =IF(AND(E11>=100000,O11>=750),"Yes","No") -> No
A12: CUST_00005 | B12: 40 | C12: Male | D12: Employed | E12: 76906.812 | F12: 84 | G12: 1260.6545 | H12: 2 | I12: 227.11026 | J12: 36 | K12: 0 | L12: 63 | M12: 5 | N12: 7 | O12: 727 | P12: 4 | Q12: 1267.3283 | R12: 2 | S12: 0 | T12: 0 | U12: 5424.0245 | V12: 0 | W12: =IF(Bank_data3[[#This Row],[credit_risk]]=1,"High Risk","Low Risk") -> Low Risk | X12: =_xlfn.IFS(B12<25,"18-24",B12<35,"25-34",B12<45,"35-44",B12<55,"45-54",TRUE(),"55+") -> 35-44 | Y12: =_xlfn.IFS(E12<50000,"Low Income",E12<100000,"Middle Income",TRUE(),"High Income") -> Middle Income | Z12: =_xlfn.IFS(O12<580,"Poor",O12<670,"Fair",O12<740,"Good",O12<800,"Very Good",TRUE(),"Excellent") -> Good | AA12: =IF(E12=0,0,Q12/E12) -> 0.016478752 | AB12: =_xlfn.IFS(G12<1000,"Low",G12<5000,"Medium",TRUE(),"High") -> Medium | AC12: =_xlfn.IFS(L12<10,"Low",L12<30,"Medium",TRUE(),"High") -> High | AD12: =IF(AND(E12>=100000,O12>=750),"Yes","No") -> No
A13: CUST_00006 | B13: 58 | C13: Female | D13: Employed | E13: 14485.73 | F13: 48 | G13: 1437.594 | H13: 3 | I13: 20 | J13: 34 | K13: 633.58911 | L13: 14 | M13: 11 | N13: 0 | O13: 754 | P13: 1 | Q13: 13356.388 | R13: 2 | S13: 1 | T13: 0 | U13: 9004.5822 | V13: 1 | W13: =IF(Bank_data3[[#This Row],[credit_risk]]=1,"High Risk","Low Risk") -> High Risk | X13: =_xlfn.IFS(B13<25,"18-24",B13<35,"25-34",B13<45,"35-44",B13<55,"45-54",TRUE(),"55+") -> 55+ | Y13: =_xlfn.IFS(E13<50000,"Low Income",E13<100000,"Middle Income",TRUE(),"High Income") -> Low Income | Z13: =_xlfn.IFS(O13<580,"Poor",O13<670,"Fair",O13<740,"Good",O13<800,"Very Good",TRUE(),"Excellent") -> Very Good | AA13: =IF(E13=0,0,Q13/E13) -> 0.92203762 | AB13: =_xlfn.IFS(G13<1000,"Low",G13<5000,"Medium",TRUE(),"High") -> Medium | AC13: =_xlfn.IFS(L13<10,"Low",L13<30,"Medium",TRUE(),"High") -> Medium | AD13: =IF(AND(E13>=100000,O13>=750),"Yes","No") -> No
A14: CUST_00007 | B14: 38 | C14: Female | D14: Employed | E14: 67355.218 | F14: 173 | G14: 1959.9972 | H14: 0 | I14: 426.24332 | J14: 7 | K14: 788.1865 | L14: 72 | M14: 15 | N14: 2 | O14: 307 | P14: 5 | Q14: 18254.854 | R14: 5 | S14: 0 | T14: 0 | U14: 12632.806 | V14: 1 | W14: =IF(Bank_data3[[#This Row],[credit_risk]]=1,"High Risk","Low Risk") -> High Risk | X14: =_xlfn.IFS(B14<25,"18-24",B14<35,"25-34",B14<45,"35-44",B14<55,"45-54",TRUE(),"55+") -> 35-44 | Y14: =_xlfn.IFS(E14<50000,"Low Income",E14<100000,"Middle Income",TRUE(),"High Income") -> Middle Income | Z14: =_xlfn.IFS(O14<580,"Poor",O14<670,"Fair",O14<740,"Good",O14<800,"Very Good",TRUE(),"Excellent") -> Poor | AA14: =IF(E14=0,0,Q14/E14) -> 0.2710236 | AB14: =_xlfn.IFS(G14<1000,"Low",G14<5000,"Medium",TRUE(),"High") -> Medium | AC14: =_xlfn.IFS(L14<10,"Low",L14<30,"Medium",TRUE(),"High") -> High | AD14: =IF(AND(E14>=100000,O14>=750),"Yes","No") -> No
A15: CUST_00008 | B15: 42 | C15: Female | D15: Employed | E15: 62980.151 | F15: 132 | G15: 2220.6996 | H15: 0 | I15: 584.18127 | J15: 42 | K15: 618.81375 | L15: 15 | M15: 5 | N15: 3 | O15: 515 | P15: 3 | Q15: 8376.6864 | R15: 7 | S15: 0 | T15: 0 | U15: 9538.7568 | V15: 1 | W15: =IF(Bank_data3[[#This Row],[credit_risk]]=1,"High Risk","Low Risk") -> High Risk | X15: =_xlfn.IFS(B15<25,"18-24",B15<35,"25-34",B15<45,"35-44",B15<55,"45-54",TRUE(),"55+") -> 35-44 | Y15: =_xlfn.IFS(E15<50000,"Low Income",E15<100000,"Middle Income",TRUE(),"High Income") -> Middle Income | Z15: =_xlfn.IFS(O15<580,"Poor",O15<670,"Fair",O15<740,"Good",O15<800,"Very Good",TRUE(),"Excellent") -> Poor | AA15: =IF(E15=0,0,Q15/E15) -> 0.13300518 | AB15: =_xlfn.IFS(G15<1000,"Low",G15<5000,"Medium",TRUE(),"High") -> Medium | AC15: =_xlfn.IFS(L15<10,"Low",L15<30,"Medium",TRUE(),"High") -> Medium | AD15: =IF(AND(E15>=100000,O15>=750),"Yes","No") -> No
A16: CUST_00009 | B16: 30 | C16: Female | D16: Self-Employed | E16: 55751.974 | F16: 99 | G16: 2527.7005 | H16: 3 | I16: 1025.4897 | J16: 2 | K16: 180.2633 | L16: 45 | M16: 1 | N16: 4 | O16: 583 | P16: 1 | Q16: 17976.627 | R16: 6 | S16: 0 | T16: 0 | U16: 2896.6703 | V16: 1 | W16: =IF(Bank_data3[[#This Row],[credit_risk]]=1,"High Risk","Low Risk") -> High Risk | X16: =_xlfn.IFS(B16<25,"18-24",B16<35,"25-34",B16<45,"35-44",B16<55,"45-54",TRUE(),"55+") -> 25-34 | Y16: =_xlfn.IFS(E16<50000,"Low Income",E16<100000,"Middle Income",TRUE(),"High Income") -> Middle Income | Z16: =_xlfn.IFS(O16<580,"Poor",O16<670,"Fair",O16<740,"Good",O16<800,"Very Good",TRUE(),"Excellent") -> Fair | AA16: =IF(E16=0,0,Q16/E16) -> 0.32243929 | AB16: =_xlfn.IFS(G16<1000,"Low",G16<5000,"Medium",TRUE(),"High") -> Medium | AC16: =_xlfn.IFS(L16<10,"Low",L16<30,"Medium",TRUE(),"High") -> High | AD16: =IF(AND(E16>=100000,O16>=750),"Yes","No") -> No
A17: CUST_00010 | B17: 30 | C17: Female | D17: Unemployed | E17: 40590.051 | F17: 205 | G17: 10 | H17: 1 | I17: 823.59283 | J17: 2 | K17: 339.64213 | L17: 43 | M17: 2 | N17: 8 | O17: 792 | P17: 3 | Q17: 9880.3197 | R17: 7 | S17: 0 | T17: 0 | U17: 1746.5996 | V17: 1 | W17: =IF(Bank_data3[[#This Row],[credit_risk]]=1,"High Risk","Low Risk") -> High Risk | X17: =_xlfn.IFS(B17<25,"18-24",B17<35,"25-34",B17<45,"35-44",B17<55,"45-54",TRUE(),"55+") -> 25-34 | Y17: =_xlfn.IFS(E17<50000,"Low Income",E17<100000,"Middle Income",TRUE(),"High Income") -> Low Income | Z17: =_xlfn.IFS(O17<580,"Poor",O17<670,"Fair",O17<740,"Good",O17<800,"Very Good",TRUE(),"Excellent") -> Very Good | AA17: =IF(E17=0,0,Q17/E17) -> 0.24341728 | AB17: =_xlfn.IFS(G17<1000,"Low",G17<5000,"Medium",TRUE(),"High") -> Low | AC17: =_xlfn.IFS(L17<10,"Low",L17<30,"Medium",TRUE(),"High") -> High | AD17: =IF(AND(E17>=100000,O17>=750),"Yes","No") -> No
A18: CUST_00011 | B18: 43 | C18: Male | D18: Employed | E18: 59050.351 | F18: 228 | G18: 858.95961 | H18: 7 | I18: 832.74091 | J18: 0 | K18: 465.153 | L18: 75 | M18: 8 | N18: 1 | O18: 738 | P18: 4 | Q18: 8443.4583 | R18: 4 | S18: 0 | T18: 0 | U18: 4463.367 | V18: 1 | W18: =IF(Bank_data3[[#This Row],[credit_risk]]=1,"High Risk","Low Risk") -> High Risk | X18: =_xlfn.IFS(B18<25,"18-24",B18<35,"25-34",B18<45,"35-44",B18<55,"45-54",TRUE(),"55+") -> 35-44 | Y18: =_xlfn.IFS(E18<50000,"Low Income",E18<100000,"Middle Income",TRUE(),"High Income") -> Middle Income | Z18: =_xlfn.IFS(O18<580,"Poor",O18<670,"Fair",O18<740,"Good",O18<800,"Very Good",TRUE(),"Excellent") -> Good | AA18: =IF(E18=0,0,Q18/E18) -> 0.14298744 | AB18: =_xlfn.IFS(G18<1000,"Low",G18<5000,"Medium",TRUE(),"High") -> Low | AC18: =_xlfn.IFS(L18<10,"Low",L18<30,"Medium",TRUE(),"High") -> High | AD18: =IF(AND(E18>=100000,O18>=750),"Yes","No") -> No
... A5006: CUST_04999 | B5006: 42 | C5006: Other | D5006: Self-Employed | E5006: 68278.151 | F5006: 136 | G5006: 1095.1232 | H5006: 7 | I5006: 1335.5331 | J5006: 11 | K5006: 569.36978 | L5006: 2 | M5006: 16 | N5006: 6 | O5006: 431 | P5006: 4 | Q5006: 17730.576 | R5006: 3 | S5006: 0 | T5006: 0 | U5006: 16552.935 | V5006: 1 | W5006: =IF(Bank_data3[[#This Row],[credit_risk]]=1,"High Risk","Low Risk") -> High Risk | X5006: =_xlfn.IFS(B5006<25,"18-24",B5006<35,"25-34",B5006<45,"35-44",B5006<55,"45-54",TRUE(),"55+") -> 35-44 | Y5006: =_xlfn.IFS(E5006<50000,"Low Income",E5006<100000,"Middle Income",TRUE(),"High Income") -> Middle Income | Z5006: =_xlfn.IFS(O5006<580,"Poor",O5006<670,"Fair",O5006<740,"Good",O5006<800,"Very Good",TRUE(),"Excellent") -> Poor | AA5006: =IF(E5006=0,0,Q5006/E5006) -> 0.25968155 | AB5006: =_xlfn.IFS(G5006<1000,"Low",G5006<5000,"Medium",TRUE(),"High") -> Medium | AC5006: =_xlfn.IFS(L5006<10,"Low",L5006<30,"Medium",TRUE(),"High") -> Low | AD5006: =IF(AND(E5006>=100000,O5006>=750),"Yes","No") -> No

Sheet Formula_Analysis
A1: Bank Credit Risk Analytics – Advanced Formula Analysis
A3: Purpose
A4: This worksheet demonstrates advanced Excel formulas used by banking analysts for customer search, risk analysis, and business reporting.
A7: Customer Search Panel
A9: Enter Customer ID | B9: CUST_00000
A11: Age | B11: =_xlfn.XLOOKUP(B9,Bank_data[customer_id],Bank_data[gender],"Not Found") -> Male
A12: Gender | B12: =_xlfn.XLOOKUP(B9,Bank_data[customer_id],Bank_data[employment_status],"Not Found") -> Unemployed
A13: Employment Status | B13: =_xlfn.XLOOKUP(B9,Bank_data[customer_id],Bank_data[annual_income],"Not Found") -> 58137.751
A14: Annual Income | B14: =_xlfn.XLOOKUP(B9,Bank_data[customer_id],Bank_data[annual_income],"Not Found") -> 58137.751
A15: Credit Score | B15: =_xlfn.XLOOKUP(B9,Bank_data[customer_id],Bank_data[credit_score],"Not Found") -> 539
A16: Credit Risk | B16: =_xlfn.XLOOKUP(B9,Bank_data3[customer_id],Bank_data3[credit_risk_label],"Not Found") -> High Risk
A17: Outstanding Debt | B17: =_xlfn.XLOOKUP(B9,Bank_data[customer_id],Bank_data[total_outstanding_debt],"Not Found") -> 14435.423
A18: Mobile Banking Logins | B18: =_xlfn.XLOOKUP(B9,Bank_data[customer_id],Bank_data[mobile_banking_logins],"Not Found") -> 9
A22: Advanced Excel Formula Demonstration
A24: Formula | B24: Business Purpose | C24: Result
A25: INDEX + MATCH | B25: Alternative customer lookup | C25: =IFERROR(INDEX(Bank_data[age],MATCH(B9,Bank_data[customer_id],0)),"Not Found") -> 58
A26: SUMIFS | B26: Total Outstanding Debt (High Risk Customers) | C26: =SUMIFS(Bank_data3[total_outstanding_debt], Bank_data3[credit_risk_label],1) -> 0
A27: COUNTIFS | B27: Count of High Risk Employed Customers | C27: =COUNTIFS(Bank_data3[credit_risk_label],1, Bank_data3[employment_status],"Employed") -> 0
A28: AVERAGEIFS | B28: Average Credit Score of Employed Customers | C28: =AVERAGEIFS(Bank_data[credit_score],Bank_data[employment_status],"Employed") -> 598.71249
A29: IFERROR | B29: Handle invalid customer IDs | C29: =IFERROR(_xlfn.XLOOKUP(B9,Bank_data[customer_id],Bank_data[age]),"Customer Not Found") -> 58
A35: Dynamic Array Functions
A37: Formula | B37: Purpose | C37: output
A38: UNIQUE | B38: Unique Employment Status | C38: {=_xlfn.UNIQUE(Bank_data[employment_status])} -> Unemployed
C39: Self-Employed
C40: Employed
A43: FILTER | B43: High Risk Customers | C43: {=_xlfn._xlws.FILTER(Bank_data3[[customer_id]:[credit_score]],Bank_data3[credit_risk_label]="High","No Records")} -> No Records
A46: Analyst Conclusion
A47: This worksheet demonstrates advanced Excel functions used in banking analytics. Interactive customer lookups, conditional aggregations, dynamic filtering, and error handling support efficient customer analysis and decision-making.

Sheet Pivot_Analysis
A1: Bank Credit Risk Analytics – Pivot Analysis
A3: This worksheet uses PivotTables to analyze customer demographics, credit risk, income, debt, and banking behavior to support lending decisions.
G5: Average Credit Score by Income Band
G6: Row Labels | H6: Average of credit_score
A7: Customer Distribution by Credit Risk | G7: High Income | H7: 580.14286
A8: Row Labels | B8: Count of customer_id | G8: Low Income | H8: 601.57934
A9: High Risk | B9: 3829 | G9: Middle Income | H9: 597.12403
A10: Low Risk | B10: 1171 | G10: Grand Total | H10: 599.3282
A11: Grand Total | B11: 5000
A19: Average Annual Income by Employment Status | G19: Outstanding Debt by Credit Risk
A20: Row Labels | B20: Average of annual_income | G20: Row Labels | H20: Sum of total_outstanding_debt
A21: High Risk | B21: 49995.724 | G21: High Risk | H21: 46704880
A22: Low Risk | B22: 49459.218 | G22: Low Risk | H22: 14162863
A23: Grand Total | B23: 49870.074 | G23: Grand Total | H23: 60867743
A33: Loan Default History by Employment Status | G33: Average Mobile Banking Logins by Age Group
A34: Count of customer_id | B34: Column Labels | G34: Row Labels | H34: Average of mobile_banking_logins
A35: Row Labels | B35: 0 | C35: 1 | D35: Grand Total | G35: 18-24 | H35: 38.28373
A36: Employed | B36: 1561 | C36: 185 | D36: 1746 | G36: 25-34 | H36: 37.738494
A37: Self-Employed | B37: 1484 | C37: 149 | D37: 1633 | G37: 35-44 | H37: 39.433202
A38: Unemployed | B38: 1468 | C38: 153 | D38: 1621 | G38: 45-54 | H38: 38.329423
A39: Grand Total | B39: 4513 | C39: 487 | D39: 5000 | G39: 55+ | H39: 40.302201
G40: Grand Total | H40: 39.028

Sheet Dashboard
A1: Bank Credit Risk Analytics Dashboard
B4: Total Customers | C4: =COUNTA(Bank_data[customer_id]) -> 5000 | D4: Average Credit Score | E4: =ROUND(AVERAGE(Bank_data[credit_score]),0) -> 599 | F4: Total Outstanding Debt | G4: =SUM(Bank_data[total_outstanding_debt]) -> 60867743 | H4: Average Annual Income | I4: =AVERAGE(Bank_data[annual_income]) -> 49870.074 | J4: High Risk Customers | K4: =COUNTIF(Bank_data3[credit_risk_label],"High Risk") -> 3829 | L4: Fraud Cases | M4: =COUNTIF(Bank_data[fraud_flag],1) -> 143

Sheet Business_insights
A1: Bank Credit Risk Analytics – Business Insights & Recommendations
A4: Project Objective
A6: This project analyzes customer banking data to evaluate credit risk, customer financial profiles, loan default patterns, and digital banking activity. The analysis uses Microsoft Excel for data cleaning, feature engineering, advanced formulas, PivotTables, and dashboard reporting to support business decision-making.|
A10: Data Cleaning Summary
A12: • Checked the dataset for missing values across all key variables.
A13: • Verified duplicate customer records and confirmed data integrity.
A14: • Validated numerical fields such as annual income, credit score, outstanding debt, and loan amount.
A15: • Standardized the dataset for consistent analysis and reporting.
A16: • Prepared the cleaned dataset for feature engineering and dashboard creation.
A18: Feature Engineering Summary
A20: • Age Group
A21: • Income Band
... A59: Skills Demonstrated
A61: Skill | B61: Status
A62: Data Cleaning | B62: ✅
A63: Data Validation | B63: ✅
A64: Feature Engineering | B64: ✅
A65: Advanced Excel Formulas | B65: ✅
A66: XLOOKUP & INDEX-MATCH | B66: ✅
A67: SUMIFS / COUNTIFS / AVERAGEIFS | B67: ✅
A68: PivotTables | B68: ✅
A69: PivotCharts | B69: ✅
A70: Interactive Dashboard | B70: ✅
A71: Banking Business Analysis | B71: ✅
A74: Conclusion
A76: This project demonstrates an end-to-end Excel analytics workflow using a banking dataset. The project includes data preparation, feature engineering, advanced Excel functions, PivotTable analysis, interactive dashboard development, and business reporting. The analysis highlights customer segmentation, credit risk distribution, debt exposure, loan default trends, and digital banking engagement, providing practical insights that support lending and risk management decisions.
